calling main
in main
creating new c
c constructing
calling c.__get() and logger.__set()
returning new logger
logger constructing
set was called
calling c.__get() and logger.__get()
returning new logger
logger constructing
get was called
got value 10
creating new d
d constructing
calling d.__get() and logger2.__set()
returning new logger2
logger2 constructing
set was called, throwing an exception
Caught exception
last line
